<?xml version="1.0" ?>
<robot name="lbr_iiwa_with_wsg50">

  <!-- connect arm to world -->
  <link name="world"/>
  <joint name="world_arm_joint" type="fixed">
    <parent link="world"/>
    <child link="base_link"/>
    <origin rpy="0.0 0.0 0" xyz="0 0 0"/>
  </joint>

  <link name="base_link">
    <visual>
      <geometry>
        <mesh filename="../meshes/ur3/visual/base.dae"/>
      </geometry>
      <material name="LightGrey">
        <color rgba="0.7 0.7 0.7 1.0"/>
      </material>
    </visual>
    <collision>
      <geometry>
        <mesh filename="../meshes/ur3/collision/base.stl"/>
      </geometry>
    </collision>
    <inertial>
      <mass value="2.0"/>
      <origin rpy="0 0 0" xyz="0.0 0.0 0.0"/>
      <inertia ixx="0.0030531654454" ixy="0.0" ixz="0.0" iyy="0.0030531654454" iyz="0.0" izz="0.005625"/>
    </inertial>
  </link>
  <joint name="shoulder_pan_joint" type="revolute">
    <parent link="base_link"/>
    <child link="shoulder_link"/>
    <origin rpy="0.0 0.0 0.0" xyz="0.0 0.0 0.1519"/>
    <axis xyz="0 0 1"/>
    <limit effort="330.0" lower="-3.14159265359" upper="3.14159265359" velocity="2.16"/>
  </joint>
  <link name="shoulder_link">
    <visual>
      <geometry>
        <mesh filename="../meshes/ur3/visual/shoulder.dae"/>
      </geometry>
      <material name="LightGrey">
        <color rgba="0.7 0.7 0.7 1.0"/>
      </material>
    </visual>
    <collision>
      <geometry>
        <mesh filename="../meshes/ur3/collision/shoulder.stl"/>
      </geometry>
    </collision>
    <inertial>
      <mass value="2.0"/>
      <origin rpy="0 0 0" xyz="0.0 0.0 0.0"/>
      <inertia ixx="0.0080931634294" ixy="0.0" ixz="0.0" iyy="0.0080931634294" iyz="0.0" izz="0.005625"/>
    </inertial>
  </link>
  <joint name="shoulder_lift_joint" type="revolute">
    <parent link="shoulder_link"/>
    <child link="upper_arm_link"/>
    <origin rpy="0.0 1.57079632679 0.0" xyz="0.0 0.1198 0.0"/>
    <axis xyz="0 1 0"/>
    <limit effort="330.0" lower="-3.14159265359" upper="3.14159265359" velocity="2.16"/>
  </joint>
  <link name="upper_arm_link">
    <visual>
      <geometry>
        <mesh filename="../meshes/ur3/visual/upperarm.dae"/>
      </geometry>
      <material name="LightGrey">
        <color rgba="0.7 0.7 0.7 1.0"/>
      </material>
    </visual>
    <collision>
      <geometry>
        <mesh filename="../meshes/ur3/collision/upperarm.stl"/>
      </geometry>
    </collision>
    <inertial>
      <mass value="3.42"/>
      <origin rpy="0 0 0" xyz="0.0 0.0 0.121825"/>
      <inertia ixx="0.0217284832211" ixy="0.0" ixz="0.0" iyy="0.0217284832211" iyz="0.0" izz="0.00961875"/>
    </inertial>
  </link>
  <joint name="elbow_joint" type="revolute">
    <parent link="upper_arm_link"/>
    <child link="forearm_link"/>
    <origin rpy="0.0 0.0 0.0" xyz="0.0 -0.0925 0.24365"/>
    <axis xyz="0 1 0"/>
    <limit effort="150.0" lower="-3.14159265359" upper="3.14159265359" velocity="3.15"/>
    <dynamics damping="0.0" friction="0.0"/>
  </joint>
  <link name="forearm_link">
    <visual>
      <geometry>
        <mesh filename="../meshes/ur3/visual/forearm.dae"/>
      </geometry>
      <material name="LightGrey">
        <color rgba="0.7 0.7 0.7 1.0"/>
      </material>
    </visual>
    <collision>
      <geometry>
        <mesh filename="../meshes/ur3/collision/forearm.stl"/>
      </geometry>
    </collision>
    <inertial>
      <mass value="1.26"/>
      <origin rpy="0 0 0" xyz="0.0 0.0 0.106625"/>
      <inertia ixx="0.00654680644378" ixy="0.0" ixz="0.0" iyy="0.00654680644378" iyz="0.0" izz="0.00354375"/>
    </inertial>
  </link>
  <joint name="wrist_1_joint" type="revolute">
    <parent link="forearm_link"/>
    <child link="wrist_1_link"/>
    <origin rpy="0.0 1.57079632679 0.0" xyz="0.0 0.0 0.21325"/>
    <axis xyz="0 1 0"/>
    <limit effort="54.0" lower="-3.14159265359" upper="3.14159265359" velocity="3.2"/>
  </joint>
  <link name="wrist_1_link">
    <visual>
      <geometry>
        <mesh filename="../meshes/ur3/visual/wrist1.dae"/>
      </geometry>
      <material name="LightGrey">
        <color rgba="0.7 0.7 0.7 1.0"/>
      </material>
    </visual>
    <collision>
      <geometry>
        <mesh filename="../meshes/ur3/collision/wrist1.stl"/>
      </geometry>
    </collision>
    <inertial>
      <mass value="0.8"/>
      <origin rpy="0 0 0" xyz="0.0 0.08505 0.0"/>
      <inertia ixx="0.002084999166" ixy="0.0" ixz="0.0" iyy="0.002084999166" iyz="0.0" izz="0.00225"/>
    </inertial>
  </link>
  <joint name="wrist_2_joint" type="revolute">
    <parent link="wrist_1_link"/>
    <child link="wrist_2_link"/>
    <origin rpy="0.0 0.0 0.0" xyz="0.0 0.08505 0.0"/>
    <axis xyz="0 0 1"/>
    <limit effort="54.0" lower="-3.14159265359" upper="3.14159265359" velocity="3.2"/>
  </joint>
  <link name="wrist_2_link">
    <visual>
      <geometry>
        <mesh filename="../meshes/ur3/visual/wrist2.dae"/>
      </geometry>
      <material name="LightGrey">
        <color rgba="0.7 0.7 0.7 1.0"/>
      </material>
    </visual>
    <collision>
      <geometry>
        <mesh filename="../meshes/ur3/collision/wrist2.stl"/>
      </geometry>
    </collision>
    <inertial>
      <mass value="0.8"/>
      <origin rpy="0 0 0" xyz="0.0 0.0 0.08535"/>
      <inertia ixx="0.002084999166" ixy="0.0" ixz="0.0" iyy="0.002084999166" iyz="0.0" izz="0.00225"/>
    </inertial>
  </link>
  <joint name="wrist_3_joint" type="revolute">
    <parent link="wrist_2_link"/>
    <child link="wrist_3_link"/>
    <origin rpy="0.0 0.0 0.0" xyz="0.0 0.0 0.08535"/>
    <axis xyz="0 1 0"/>
    <limit effort="54.0" lower="-3.14159265359" upper="3.14159265359" velocity="3.2"/>
  </joint>
  <link name="wrist_3_link">
    <visual>
      <geometry>
        <mesh filename="../meshes/ur3/visual/wrist3.dae"/>
      </geometry>
      <material name="LightGrey">
        <color rgba="0.7 0.7 0.7 1.0"/>
      </material>
    </visual>
    <collision>
      <geometry>
        <mesh filename="../meshes/ur3/collision/wrist3.stl"/>
      </geometry>
    </collision>
    <inertial>
      <mass value="0.35"/>
      <origin rpy="1.57079632679 0 0" xyz="0.0 0.0619 0.0"/>
      <inertia ixx="0.00013626661216" ixy="0.0" ixz="0.0" iyy="0.00013626661216" iyz="0.0" izz="0.0001792"/>
    </inertial>
  </link>
  <joint name="ee_fixed_joint" type="fixed">
    <parent link="wrist_3_link"/>
    <child link="ee_link"/>
    <origin rpy="0.0 0.0 1.57079632679" xyz="0.0 0.0819 0.0"/>
  </joint>
  <link name="ee_link">
    <collision>
      <geometry>
        <box size="0.01 0.01 0.01"/>
      </geometry>
      <origin rpy="0 0 0" xyz="-0.01 0 0"/>
    </collision>
  </link>

  <joint name="lbr_iiwa_with_wsg50__gripper_to_arm" type="continuous">
    <parent link="ee_link"/>
    <child link="lbr_iiwa_with_wsg50__base_link"/>
    <origin rpy="0  0  0" xyz="0     0     0.044"/>
    <axis xyz="0  0  1"/>
    <limit effort="0" lower="0" upper="0" velocity="0"/>
  </joint>

  <joint name="lbr_iiwa_with_wsg50__base_left_finger_joint" type="revolute">
    <parent link="lbr_iiwa_with_wsg50__base_link"/>
    <child link="lbr_iiwa_with_wsg50__left_finger"/>
    <origin rpy="0   -0.05  0" xyz="0     0.024  0.045"/>
    <axis xyz="0  1  0"/>
    <limit effort="100.0" lower="-10.4" upper="10.01" velocity="0.0"/>
  </joint>
  <joint name="lbr_iiwa_with_wsg50__left_finger_base_joint" type="fixed">
    <parent link="lbr_iiwa_with_wsg50__left_finger"/>
    <child link="lbr_iiwa_with_wsg50__left_finger_base"/>
    <origin rpy="0   -0.25  0" xyz="-0.00099  0       0.08015"/>
    <axis xyz="0  0  0"/>
    <limit effort="0" lower="0" upper="0" velocity="0"/>
  </joint>
  <joint name="lbr_iiwa_with_wsg50__left_base_tip_joint" type="revolute">
    <parent link="lbr_iiwa_with_wsg50__left_finger_base"/>
    <child link="lbr_iiwa_with_wsg50__left_finger_tip"/>
    <origin rpy="0   0.5  0" xyz="0.0034   0       0.06175"/>
    <axis xyz="0  1  0"/>
    <limit effort="0.0" lower="-10.1" upper="10.3" velocity="0.0"/>
  </joint>
  <joint name="lbr_iiwa_with_wsg50__base_right_finger_joint" type="revolute">
    <parent link="lbr_iiwa_with_wsg50__base_link"/>
    <child link="lbr_iiwa_with_wsg50__right_finger"/>
    <origin rpy="0    0.05  0" xyz="0     0.024  0.045"/>
    <axis xyz="0  1  0"/>
    <limit effort="100.0" lower="-10.01" upper="10.4" velocity="0.0"/>
  </joint>
  <joint name="lbr_iiwa_with_wsg50__right_finger_base_joint" type="fixed">
    <parent link="lbr_iiwa_with_wsg50__right_finger"/>
    <child link="lbr_iiwa_with_wsg50__right_finger_base"/>
    <origin rpy="0    0.25  0" xyz="0.00099  0       0.08015"/>
    <axis xyz="0  0  0"/>
    <limit effort="0" lower="0" upper="0" velocity="0"/>
  </joint>
  <joint name="lbr_iiwa_with_wsg50__right_base_tip_joint" type="revolute">
    <parent link="lbr_iiwa_with_wsg50__right_finger_base"/>
    <child link="lbr_iiwa_with_wsg50__right_finger_tip"/>
    <origin rpy="0  -0.5  0" xyz="-0.0034   0       0.06175"/>
    <axis xyz="0  1  0"/>
    <limit effort="0.0" lower="-10.3" upper="10.1" velocity="0.0"/>
  </joint>

  
  <link name="lbr_iiwa_with_wsg50__base_link">
    <inertial>
      <mass value="0.2"/>
      <origin rpy="0  0  0" xyz="0  0  0"/>
      <inertia ixx="1" ixy="0" ixz="0" iyy="1" iyz="0" izz="1"/>
    </inertial>
    <collision name="lbr_iiwa_with_wsg50__base_link_collision">
      <origin rpy="0  0  0" xyz="0  0  0"/>
      <geometry>
        <box size="0.05 0.05 0.1"/>
      </geometry>
    </collision>
    <visual name="lbr_iiwa_with_wsg50__base_link_visual">
      <origin rpy="0  0  0" xyz="0  0  0"/>
      <geometry>
        <box size="0.05 0.05 0.1"/>
      </geometry>
    </visual>
  </link>
  <link name="lbr_iiwa_with_wsg50__left_finger">
    <inertial>
      <mass value="0.2"/>
      <origin rpy="0  0  0" xyz="0    0    0.04"/>
      <inertia ixx="0.1" ixy="0" ixz="0" iyy="0.1" iyz="0" izz="0.1"/>
    </inertial>
    <collision name="lbr_iiwa_with_wsg50__left_finger_collision">
      <origin rpy="0  0  0" xyz="0    0    0.04"/>
      <geometry>
        <box size="0.01 0.01 0.08"/>
      </geometry>
    </collision>
    <visual name="lbr_iiwa_with_wsg50__left_finger_visual">
      <origin rpy="0  0  0" xyz="0    0    0.04"/>
      <geometry>
        <box size="0.01 0.01 0.08"/>
      </geometry>
    </visual>
  </link>
  <link name="lbr_iiwa_with_wsg50__left_finger_base">
    <inertial>
      <mass value="0.2"/>
      <origin rpy="0  0  0" xyz="-0.003  0     0.04"/>
      <inertia ixx="0.1" ixy="0" ixz="0" iyy="0.1" iyz="0" izz="0.1"/>
    </inertial>
    <collision name="lbr_iiwa_with_wsg50__left_finger_base_collision">
      <origin rpy="0  0  0" xyz="0  0  0"/>
      <geometry>
        <mesh filename="meshes/finger_base_left.stl" scale="1 1 1"/>
      </geometry>
    </collision>
    <visual name="lbr_iiwa_with_wsg50__left_finger_base_visual">
      <origin rpy="0  0  0" xyz="0  0  0"/>
      <geometry>
        <mesh filename="meshes/finger_base_left.stl" scale="1 1 1"/>
      </geometry>
    </visual>
  </link>
  <link name="lbr_iiwa_with_wsg50__left_finger_tip">
    <inertial>
      <mass value="0.2"/>
      <origin rpy="0  0  0" xyz="-0.005  0     0.026"/>
      <inertia ixx="0.1" ixy="0" ixz="0" iyy="0.1" iyz="0" izz="0.1"/>
    </inertial>
    <collision name="lbr_iiwa_with_wsg50__left_finger_tip_collision">
      <origin rpy="0  0  0" xyz="0  0  0"/>
      <geometry>
        <mesh filename="meshes/finger_tip_left.stl" scale="1 1 1"/>
      </geometry>
    </collision>
    <visual name="lbr_iiwa_with_wsg50__left_finger_tip_visual">
      <origin rpy="0  0  0" xyz="0  0  0"/>
      <geometry>
        <mesh filename="meshes/finger_tip_left.stl" scale="1 1 1"/>
      </geometry>
    </visual>
  </link>
  <link name="lbr_iiwa_with_wsg50__right_finger">
    <inertial>
      <mass value="0.2"/>
      <origin rpy="0  0  0" xyz="0    0    0.04"/>
      <inertia ixx="0.1" ixy="0" ixz="0" iyy="0.1" iyz="0" izz="0.1"/>
    </inertial>
    <collision name="lbr_iiwa_with_wsg50__right_finger_collision">
      <origin rpy="0  0  0" xyz="0    0    0.04"/>
      <geometry>
        <box size="0.01 0.01 0.08"/>
      </geometry>
    </collision>
    <visual name="lbr_iiwa_with_wsg50__right_finger_visual">
      <origin rpy="0  0  0" xyz="0    0    0.04"/>
      <geometry>
        <box size="0.01 0.01 0.08"/>
      </geometry>
    </visual>
  </link>
  <link name="lbr_iiwa_with_wsg50__right_finger_base">
    <inertial>
      <mass value="0.2"/>
      <origin rpy="0  0  0" xyz="0.003  0     0.04"/>
      <inertia ixx="0.1" ixy="0" ixz="0" iyy="0.1" iyz="0" izz="0.1"/>
    </inertial>
    <collision name="lbr_iiwa_with_wsg50__right_finger_base_collision">
      <origin rpy="0  0  0" xyz="0  0  0"/>
      <geometry>
        <mesh filename="meshes/finger_base_right.stl" scale="1 1 1"/>
      </geometry>
    </collision>
    <visual name="lbr_iiwa_with_wsg50__right_finger_base_visual">
      <origin rpy="0  0  0" xyz="0  0  0"/>
      <geometry>
        <mesh filename="meshes/finger_base_right.stl" scale="1 1 1"/>
      </geometry>
    </visual>
  </link>
  <link name="lbr_iiwa_with_wsg50__right_finger_tip">
    <inertial>
      <mass value="0.2"/>
      <origin rpy="0  0  0" xyz="0.005  0     0.026"/>
      <inertia ixx="0.1" ixy="0" ixz="0" iyy="0.1" iyz="0" izz="0.1"/>
    </inertial>
    <collision name="lbr_iiwa_with_wsg50__right_finger_tip_collision">
      <origin rpy="0  0  0" xyz="0  0  0"/>
      <geometry>
        <mesh filename="meshes/finger_tip_right.stl" scale="1 1 1"/>
      </geometry>
    </collision>
    <visual name="lbr_iiwa_with_wsg50__right_finger_visual">
      <origin rpy="0  0  0" xyz="0  0  0"/>
      <geometry>
        <mesh filename="meshes/finger_tip_right.stl" scale="1 1 1"/>
      </geometry>
    </visual>
  </link>
</robot>